Workbook
Name LIBRE_JOURNAL: JOURNAL!$A$1:$F$20
Name LIBRE_RAPPORT: RAPPORT!$A$1:$E$25
Name P_DOSSIER: PARAMETRES!$B$21
Name P_TYPE: RAPPORT!$B$4
Name P_VALEUR: RAPPORT!$B$5
Name R_CONTROLE: REPONSES!$B$26
Name R_ECART_AGENCES: REPONSES!$B$20
Name R_ECART_FAMILLES: REPONSES!$B$21
Name R_ECART_SOURCES: REPONSES!$B$16

Sheet README
A1: README
A3: À quoi sert ce classeur | B3: Produire les douze rapports mensuels de BAOBAB — six agences et six familles de produits — à partir des commandes des 200 clients grands comptes. Un clic, douze PDF nommés, un journal d'exécution.
A4: D'où viennent les données | B4: 200 classeurs clients au format identique, reçus par messagerie et déposés dans le dossier J10_Clients. Consolidés dans DONNEES, récapitulés fichier par fichier dans SOURCES. Période : août 2026.
A5: Les quinze fichiers qui ne sont pas au format | B5: Quatre sont vides — le client n'a rien commandé ce mois-ci. Six portent une ligne TOTAL sous le tableau, qu'il ne faut surtout pas additionner. Trois ont une colonne Remise_Pct en plus. Deux ont une feuille nommée COMMANDES au lieu de Commandes. La colonne Anomalie de SOURCES les liste tous les quinze.
A6: Les taux de change | B6: Figés pour le mois : 3 145,80 CDF et 648,20 XOF comme XAF pour 1 USD. Le franc CFA Ouest et le franc CFA Central sont arrimés à l'euro à la même parité : leur taux face au dollar est identique. Ce n'est pas une coquille.
A7: Comment on convertit, et pourquoi ça compte | B7: Ligne à ligne, jamais sur le total. Les deux méthodes sont défendables ; elles écartent de 0,54 USD sur ce mois. Ce qui n'est pas défendable, c'est de ne pas savoir laquelle on a utilisée.
A8: Comment lancer la production | B8: Bouton « Produire les douze rapports » sur la feuille PARAMETRES. Le dossier de sortie est un sous-dossier du dossier de ce classeur, nommé dans PARAMETRES!B21. Durée observée : environ 40 secondes.
A9: Ce qu'il faut faire si ça casse | B9: Lire la colonne Message du JOURNAL : elle nomme le rapport qui a échoué et la raison. Les trois causes vues jusqu'ici : le dossier de sortie n'existe pas, un PDF du même nom est ouvert dans un lecteur, et le classeur a été ouvert depuis la messagerie sans avoir été enregistré ailleurs d'abord.
A10: Ce que ce classeur ne fait pas | B10: Il n'envoie aucun courriel, il ne va pas chercher les fichiers clients tout seul, et il ne détecte pas un client qui aurait oublié d'envoyer son fichier. Trois manques connus, écrits ici.
A11: Livraison | B11: En .zip, jamais en .xlsm nu : les pièces jointes .xlsm sont bloquées par la plupart des messageries, et le Mark of the Web désactive les macros d'un fichier venu d'Internet. La procédure de déblocage est dans le fichier LISEZ-MOI.txt du zip.
A12: Journal des versions | B12: v1.0 — septembre 2026.

Sheet SOURCES
A1: Les 200 classeurs reçus — un récapitulatif par fichier
A2: Produit par la consolidation. C'est cette feuille qui permet de réconcilier : si elle ne tombe pas d'accord avec DONNEES, un fichier a été lu deux fois ou pas du tout.
A4: Fichier | B4: Code_Client | C4: Client | D4: Agence | E4: Devise | F4: Lignes | G4: Total_Local | H4: Total_USD | I4: Total_USD_direct | J4: Anomalie
A5: C0001_Alimentation_Ndong_SARLU.xlsx | B5: C0001 | C5: Alimentation Ndong SARLU | D5: Dakar | E5: XOF | F5: 25 | G5: 4204806 | H5: 6486.91 | I5: 6486.9
A6: C0002_Établissements_Atangana.xlsx | B6: C0002 | C6: Établissements Atangana | D6: Kinshasa | E6: CDF | F6: 16 | G6: 3060274 | H6: 972.8 | I6: 972.81
A7: C0003_Négoce_Lubaki_SARL.xlsx | B7: C0003 | C7: Négoce Lubaki SARL | D7: Abidjan | E7: XOF | F7: 27 | G7: 4055570 | H7: 6256.66 | I7: 6256.66
A8: C0004_Société_Mbarga_Sarl.xlsx | B8: C0004 | C8: Société Mbarga Sarl | D8: Douala | E8: XAF | F8: 16 | G8: 1198497 | H8: 1848.97 | I8: 1848.96
A9: C0005_Établissements_Ndong_SA.xlsx | B9: C0005 | C9: Établissements Ndong SA | D9: Kinshasa | E9: CDF | F9: 20 | G9: 15162088 | H9: 4819.77 | I9: 4819.79
A10: C0006_Comptoir_Traoré.xlsx | B10: C0006 | C10: Comptoir Traoré | D10: Abidjan | E10: XOF | F10: 28 | G10: 2342018 | H10: 3613.07 | I10: 3613.11 | J10: ligne TOTAL en bas
A11: C0007_Établissements_Mutombo_SA.xlsx | B11: C0007 | C11: Établissements Mutombo SA | D11: Kinshasa | E11: CDF | F11: 17 | G11: 9397570 | H11: 2987.34 | I11: 2987.34
A12: C0008_Alimentation_Nzé_SA.xlsx | B12: C0008 | C12: Alimentation Nzé SA | D12: Douala | E12: XAF | F12: 27 | G12: 4045819 | H12: 6241.61 | I12: 6241.62
A13: C0009_Ets_Kalala.xlsx | B13: C0009 | C13: Ets Kalala | D13: Libreville | E13: XAF | F13: 14 | G13: 4601156 | H13: 7098.35 | I13: 7098.36
A14: C0010_Alimentation_Lubaki_Sarl.xlsx | B14: C0010 | C14: Alimentation Lubaki Sarl | D14: Abidjan | E14: XOF | F14: 11 | G14: 270124 | H14: 416.72 | I14: 416.73
A15: C0011_Maison_Ilunga_Sarl.xlsx | B15: C0011 | C15: Maison Ilunga Sarl | D15: Lubumbashi | E15: CDF | F15: 68 | G15: 157512668 | H15: 50070.81 | I15: 50070.78
A16: C0012_Distribution_Moussavou.xlsx | B16: C0012 | C16: Distribution Moussavou | D16: Douala | E16: XAF | F16: 33 | G16: 7491053 | H16: 11556.7 | I16: 11556.7
A17: C0013_Ets_Diop.xlsx | B17: C0013 | C17: Ets Diop | D17: Abidjan | E17: XOF | F17: 16 | G17: 899933 | H17: 1388.36 | I17: 1388.36
A18: C0014_Maison_Lubaki_Sarl.xlsx | B18: C0014 | C18: Maison Lubaki Sarl | D18: Kinshasa | E18: CDF | F18: 24 | G18: 38886126 | H18: 12361.27 | I18: 12361.28
A19: C0015_Entreprise_Mukendi_SARL.xlsx | B19: C0015 | C19: Entreprise Mukendi SARL | D19: Douala | E19: XAF | F19: 40 | G19: 4771986 | H19: 7361.89 | I19: 7361.9
A20: C0016_Alimentation_Bemba_SARL.xlsx | B20: C0016 | C20: Alimentation Bemba SARL | D20: Libreville | E20: XAF | F20: 27 | G20: 9497664 | H20: 14652.38 | I20: 14652.37
A21: C0017_Alimentation_Tshibangu_SARLU.xlsx | B21: C0017 | C21: Alimentation Tshibangu SARLU | D21: Douala | E21: XAF | F21: 0 | G21: 0 | H21: 0 | I21: 0 | J21: vide
A22: C0018_Établissements_Kouadio_Sarl.xlsx | B22: C0018 | C22: Établissements Kouadio Sarl | D22: Kinshasa | E22: CDF | F22: 23 | G22: 8887219 | H22: 2825.09 | I22: 2825.11
A23: C0019_Maison_Mukendi.xlsx | B23: C0019 | C23: Maison Mukendi | D23: Lubumbashi | E23: CDF | F23: 10 | G23: 2084579 | H23: 662.65 | I23: 662.65
A24: C0020_Comptoir_Diop_SA.xlsx | B24: C0020 | C24: Comptoir Diop SA | D24: Kinshasa | E24: CDF | F24: 22 | G24: 10179476 | H24: 3235.91 | I24: 3235.89
A25: C0021_Négoce_Cissé_SARLU.xlsx | B25: C0021 | C25: Négoce Cissé SARLU | D25: Kinshasa | E25: CDF | F25: 6 | G25: 1906207 | H25: 605.95 | I25: 605.95
A26: C0022_Comptoir_Camara_&_Fils.xlsx | B26: C0022 | C26: Comptoir Camara & Fils | D26: Dakar | E26: XOF | F26: 18 | G26: 5144334 | H26: 7936.33 | I26: 7936.34
A27: C0023_Groupe_Diop_&_Fils.xlsx | B27: C0023 | C27: Groupe Diop & Fils | D27: Kinshasa | E27: CDF | F27: 30 | G27: 37272791 | H27: 11848.43 | I27: 11848.43 | J27: colonne Remise_Pct en plus
A28: C0024_Négoce_Kamga.xlsx | B28: C0024 | C28: Négoce Kamga | D28: Kinshasa | E28: CDF | F28: 51 | G28: 48484983 | H28: 15412.62 | I28: 15412.61
A29: C0025_Entreprise_Ndiaye_SA.xlsx | B29: C0025 | C29: Entreprise Ndiaye SA | D29: Dakar | E29: XOF | F29: 31 | G29: 8841255 | H29: 13639.72 | I29: 13639.7
A30: C0026_Entreprise_Mukendi.xlsx | B30: C0026 | C30: Entreprise Mukendi | D30: Lubumbashi | E30: CDF | F30: 34 | G30: 18561369 | H30: 5900.36 | I30: 5900.37
A31: C0027_Société_Fotso_SARLU.xlsx | B31: C0027 | C31: Société Fotso SARLU | D31: Lubumbashi | E31: CDF | F31: 31 | G31: 15313519 | H31: 4867.92 | I31: 4867.93
A32: C0028_Ets_Kamga_Sarl.xlsx | B32: C0028 | C32: Ets Kamga Sarl | D32: Kinshasa | E32: CDF | F32: 20 | G32: 3386379 | H32: 1076.5 | I32: 1076.48
A33: C0029_Distribution_Kamga_&_Fils.xlsx | B33: C0029 | C33: Distribution Kamga & Fils | D33: Abidjan | E33: XOF | F33: 20 | G33: 1356123 | H33: 2092.16 | I33: 2092.14
A34: C0030_Entreprise_Tshibangu_SA.xlsx | B34: C0030 | C34: Entreprise Tshibangu SA | D34: Kinshasa | E34: CDF | F34: 13 | G34: 4183856 | H34: 1329.98 | I34: 1329.98
A35: C0031_Négoce_Ilunga_SARLU.xlsx | B35: C0031 | C35: Négoce Ilunga SARLU | D35: Kinshasa | E35: CDF | F35: 31 | G35: 28288261 | H35: 8992.39 | I35: 8992.39
A36: C0032_Alimentation_Traoré_SARL.xlsx | B36: C0032 | C36: Alimentation Traoré SARL | D36: Lubumbashi | E36: CDF | F36: 8 | G36: 6184765 | H36: 1966.04 | I36: 1966.04
A37: C0033_Négoce_Bemba_SA.xlsx | B37: C0033 | C37: Négoce Bemba SA | D37: Lubumbashi | E37: CDF | F37: 60 | G37: 50947033 | H37: 16195.2 | I37: 16195.25
A38: C0034_Négoce_Fotso_SARLU.xlsx | B38: C0034 | C38: Négoce Fotso SARLU | D38: Libreville | E38: XAF | F38: 23 | G38: 1284060 | H38: 1980.97 | I38: 1980.96 | J38: feuille COMMANDES en majuscules
A39: C0035_Groupe_Bamba_&_Fils.xlsx | B39: C0035 | C39: Groupe Bamba & Fils | D39: Douala | E39: XAF | F39: 34 | G39: 3875864 | H39: 5979.38 | I39: 5979.43
A40: C0036_Maison_Koffi_SARLU.xlsx | B40: C0036 | C40: Maison Koffi SARLU | D40: Lubumbashi | E40: CDF | F40: 13 | G40: 3760182 | H40: 1195.32 | I40: 1195.3
A41: C0037_Ets_Fall_SARLU.xlsx | B41: C0037 | C41: Ets Fall SARLU | D41: Abidjan | E41: XOF | F41: 19 | G41: 1890848 | H41: 2917.05 | I41: 2917.07
...

Sheet DONNEES
A1: La consolidation — une ligne par ligne de commande
A2: 5637 lignes, août 2026. Conversion ligne à ligne, au taux du mois de la devise de l'agence.
A4: Date | B4: Code_Client | C4: Client | D4: Agence | E4: Famille | F4: Produit | G4: Quantite | H4: PU_Local | I4: Montant_Local | J4: Devise | K4: Taux | L4: Montant_USD
A5: 46235 | B5: C0002 | C5: Établissements Atangana | D5: Kinshasa | E5: Riz | F5: Riz parfumé 25 kg | G5: 2 | H5: 78446 | I5: 156892 | J5: CDF | K5: 3145.8 | L5: 49.87
A6: 46235 | B6: C0003 | C6: Négoce Lubaki SARL | D6: Abidjan | E6: Farine | F6: Farine de blé 50 kg | G6: 11 | H6: 18747 | I6: 206217 | J6: XOF | K6: 648.2 | L6: 318.14
A7: 46235 | B7: C0004 | C7: Société Mbarga Sarl | D7: Douala | E7: Savons | F7: Détergent lot 12 | G7: 12 | H7: 9801 | I7: 117612 | J7: XAF | K7: 648.2 | L7: 181.44
A8: 46235 | B8: C0004 | C8: Société Mbarga Sarl | D8: Douala | E8: Boissons | F8: Jus concentré pack 6 | G8: 7 | H8: 5546 | I8: 38822 | J8: XAF | K8: 648.2 | L8: 59.89
A9: 46235 | B9: C0004 | C9: Société Mbarga Sarl | D9: Douala | E9: Conserves | F9: Sardines 125 g | G9: 13 | H9: 557 | I9: 7241 | J9: XAF | K9: 648.2 | L9: 11.17
A10: 46235 | B10: C0005 | C10: Établissements Ndong SA | D10: Kinshasa | E10: Boissons | F10: Jus concentré pack 6 | G10: 3 | H10: 27903 | I10: 83709 | J10: CDF | K10: 3145.8 | L10: 26.61
A11: 46235 | B11: C0006 | C11: Comptoir Traoré | D11: Abidjan | E11: Farine | F11: Farine de blé 50 kg | G11: 31 | H11: 19615 | I11: 608065 | J11: XOF | K11: 648.2 | L11: 938.08
A12: 46235 | B12: C0006 | C12: Comptoir Traoré | D12: Abidjan | E12: Savons | F12: Savon de ménage lot 24 | G12: 2 | H12: 6188 | I12: 12376 | J12: XOF | K12: 648.2 | L12: 19.09
A13: 46235 | B13: C0007 | C13: Établissements Mutombo SA | D13: Kinshasa | E13: Boissons | F13: Boisson gazeuse pack 6 | G13: 3 | H13: 12963 | I13: 38889 | J13: CDF | K13: 3145.8 | L13: 12.36
A14: 46235 | B14: C0007 | C14: Établissements Mutombo SA | D14: Kinshasa | E14: Farine | F14: Farine de maïs 25 kg | G14: 39 | H14: 43710 | I14: 1704690 | J14: CDF | K14: 3145.8 | L14: 541.89
A15: 46235 | B15: C0008 | C15: Alimentation Nzé SA | D15: Douala | E15: Huiles | F15: Huile végétale 5 L | G15: 12 | H15: 4052 | I15: 48624 | J15: XAF | K15: 648.2 | L15: 75.01
A16: 46235 | B16: C0009 | C16: Ets Kalala | D16: Libreville | E16: Savons | F16: Détergent lot 12 | G16: 16 | H16: 9737 | I16: 155792 | J16: XAF | K16: 648.2 | L16: 240.35
... A5641: 46265 | B5641: C0199 | C5641: Société Kamga SA | D5641: Libreville | E5641: Huiles | F5641: Huile végétale 5 L | G5641: 3 | H5641: 4234 | I5641: 12702 | J5641: XAF | K5641: 648.2 | L5641: 19.6

Sheet PARAMETRES
A1: Ce que la macro doit produire
A2: Douze rapports : six agences et six familles. Deux découpes du même total — et chacune doit se re-sommer au consolidé.
A4: Type | B4: Valeur | C4: Nom_Fichier | D4: Total_USD
A5: Agence | B5: Kinshasa | C5: 2026-08_Agence_Kinshasa.pdf | D5: =SUMIFS(t_Ventes[Montant_USD],t_Ventes[Agence],IF($A5="Agence",$B5,"*"),t_Ventes[Famille],IF($A5="Famille",$B5,"*")) -> 387868.97
A6: Agence | B6: Lubumbashi | C6: 2026-08_Agence_Lubumbashi.pdf | D6: =SUMIFS(t_Ventes[Montant_USD],t_Ventes[Agence],IF($A6="Agence",$B6,"*"),t_Ventes[Famille],IF($A6="Famille",$B6,"*")) -> 219953.12
A7: Agence | B7: Abidjan | C7: 2026-08_Agence_Abidjan.pdf | D7: =SUMIFS(t_Ventes[Montant_USD],t_Ventes[Agence],IF($A7="Agence",$B7,"*"),t_Ventes[Famille],IF($A7="Famille",$B7,"*")) -> 402516.35
A8: Agence | B8: Dakar | C8: 2026-08_Agence_Dakar.pdf | D8: =SUMIFS(t_Ventes[Montant_USD],t_Ventes[Agence],IF($A8="Agence",$B8,"*"),t_Ventes[Famille],IF($A8="Famille",$B8,"*")) -> 162151.38
A9: Agence | B9: Douala | C9: 2026-08_Agence_Douala.pdf | D9: =SUMIFS(t_Ventes[Montant_USD],t_Ventes[Agence],IF($A9="Agence",$B9,"*"),t_Ventes[Famille],IF($A9="Famille",$B9,"*")) -> 194444.31
A10: Agence | B10: Libreville | C10: 2026-08_Agence_Libreville.pdf | D10: =SUMIFS(t_Ventes[Montant_USD],t_Ventes[Agence],IF($A10="Agence",$B10,"*"),t_Ventes[Famille],IF($A10="Famille",$B10,"*")) -> 305853.78
A11: Famille | B11: Huiles | C11: 2026-08_Famille_Huiles.pdf | D11: =SUMIFS(t_Ventes[Montant_USD],t_Ventes[Agence],IF($A11="Agence",$B11,"*"),t_Ventes[Famille],IF($A11="Famille",$B11,"*")) -> 279286.53
A12: Famille | B12: Riz | C12: 2026-08_Famille_Riz.pdf | D12: =SUMIFS(t_Ventes[Montant_USD],t_Ventes[Agence],IF($A12="Agence",$B12,"*"),t_Ventes[Famille],IF($A12="Famille",$B12,"*")) -> 790854.58
A13: Famille | B13: Farine | C13: 2026-08_Famille_Farine.pdf | D13: =SUMIFS(t_Ventes[Montant_USD],t_Ventes[Agence],IF($A13="Agence",$B13,"*"),t_Ventes[Famille],IF($A13="Famille",$B13,"*")) -> 339712.77
A14: Famille | B14: Boissons | C14: 2026-08_Famille_Boissons.pdf | D14: =SUMIFS(t_Ventes[Montant_USD],t_Ventes[Agence],IF($A14="Agence",$B14,"*"),t_Ventes[Famille],IF($A14="Famille",$B14,"*")) -> 81306.67
A15: Famille | B15: Savons | C15: 2026-08_Famille_Savons.pdf | D15: =SUMIFS(t_Ventes[Montant_USD],t_Ventes[Agence],IF($A15="Agence",$B15,"*"),t_Ventes[Famille],IF($A15="Famille",$B15,"*")) -> 159883.22
A16: Famille | B16: Conserves | C16: 2026-08_Famille_Conserves.pdf | D16: =SUMIFS(t_Ventes[Montant_USD],t_Ventes[Agence],IF($A16="Agence",$B16,"*"),t_Ventes[Famille],IF($A16="Famille",$B16,"*")) -> 21744.14
A19: Les paramètres d'exécution
A21: Dossier de sortie | B21: Rapports | C21: un sous-dossier du dossier de ce classeur — jamais un chemin absolu
A22: Période | B22: 2026-08 | C22: sert à nommer les fichiers
A23: Taux CDF | B23: 3145.8 | C23: figé pour le mois
A24: Taux XOF | B24: 648.2 | C24: arrimé à l'euro
A25: Taux XAF | B25: 648.2 | C25: même parité que le XOF — ce n'est pas une coquille

Sheet RAPPORT
A1: BAOBAB — rapport de synthèse
A2: Août 2026
A4: Découpe | B4: Agence | C4: ← ces deux cellules sont écrites par la macro, à chaque tour
A5: Valeur | B5: Kinshasa
A7: Chiffre d'affaires | B7: =SUMIFS(t_Ventes[Montant_USD],t_Ventes[Agence],IF($B$4="Agence",$B$5,"*"),t_Ventes[Famille],IF($B$4="Famille",$B$5,"*")) -> 387868.97
A8: Lignes de commande | B8: =COUNTIFS(t_Ventes[Agence],IF($B$4="Agence",$B$5,"*"),t_Ventes[Famille],IF($B$4="Famille",$B$5,"*")) -> 1567
A9: Quantité totale | B9: =SUMIFS(t_Ventes[Quantite],t_Ventes[Agence],IF($B$4="Agence",$B$5,"*"),t_Ventes[Famille],IF($B$4="Famille",$B$5,"*")) -> 28539
A10: Panier moyen par ligne | B10: =IF(B8=0,0,B7/B8) -> 247.52327
A11: Part du consolidé | B11: =IF(REPONSES!$B$15=0,0,B7/REPONSES!$B$15) -> 0.23186978
A13: Le détail
A15: Ligne | B15: Chiffre d'affaires | C15: Lignes | D15: Part
A16: =IF($B$4="Agence",INDEX(PARAMETRES!$B$11:$B$16,1),INDEX(PARAMETRES!$B$5:$B$10,1)) -> Huiles | B16: =SUMIFS(t_Ventes[Montant_USD],t_Ventes[Agence],IF($B$4="Agence",$B$5,$A16),t_Ventes[Famille],IF($B$4="Agence",$A16,$B$5)) -> 63019.82 | C16: =COUNTIFS(t_Ventes[Agence],IF($B$4="Agence",$B$5,$A16),t_Ventes[Famille],IF($B$4="Agence",$A16,$B$5)) -> 338 | D16: =IF($B$7=0,0,B16/$B$7) -> 0.16247709
A17: =IF($B$4="Agence",INDEX(PARAMETRES!$B$11:$B$16,2),INDEX(PARAMETRES!$B$5:$B$10,2)) -> Riz | B17: =SUMIFS(t_Ventes[Montant_USD],t_Ventes[Agence],IF($B$4="Agence",$B$5,$A17),t_Ventes[Famille],IF($B$4="Agence",$A17,$B$5)) -> 183202.77 | C17: =COUNTIFS(t_Ventes[Agence],IF($B$4="Agence",$B$5,$A17),t_Ventes[Famille],IF($B$4="Agence",$A17,$B$5)) -> 391 | D17: =IF($B$7=0,0,B17/$B$7) -> 0.4723316
A18: =IF($B$4="Agence",INDEX(PARAMETRES!$B$11:$B$16,3),INDEX(PARAMETRES!$B$5:$B$10,3)) -> Farine | B18: =SUMIFS(t_Ventes[Montant_USD],t_Ventes[Agence],IF($B$4="Agence",$B$5,$A18),t_Ventes[Famille],IF($B$4="Agence",$A18,$B$5)) -> 75221.28 | C18: =COUNTIFS(t_Ventes[Agence],IF($B$4="Agence",$B$5,$A18),t_Ventes[Famille],IF($B$4="Agence",$A18,$B$5)) -> 267 | D18: =IF($B$7=0,0,B18/$B$7) -> 0.19393477
A19: =IF($B$4="Agence",INDEX(PARAMETRES!$B$11:$B$16,4),INDEX(PARAMETRES!$B$5:$B$10,4)) -> Boissons | B19: =SUMIFS(t_Ventes[Montant_USD],t_Ventes[Agence],IF($B$4="Agence",$B$5,$A19),t_Ventes[Famille],IF($B$4="Agence",$A19,$B$5)) -> 16832.54 | C19: =COUNTIFS(t_Ventes[Agence],IF($B$4="Agence",$B$5,$A19),t_Ventes[Famille],IF($B$4="Agence",$A19,$B$5)) -> 193 | D19: =IF($B$7=0,0,B19/$B$7) -> 0.043397491
A20: =IF($B$4="Agence",INDEX(PARAMETRES!$B$11:$B$16,5),INDEX(PARAMETRES!$B$5:$B$10,5)) -> Savons | B20: =SUMIFS(t_Ventes[Montant_USD],t_Ventes[Agence],IF($B$4="Agence",$B$5,$A20),t_Ventes[Famille],IF($B$4="Agence",$A20,$B$5)) -> 44918.44 | C20: =COUNTIFS(t_Ventes[Agence],IF($B$4="Agence",$B$5,$A20),t_Ventes[Famille],IF($B$4="Agence",$A20,$B$5)) -> 169 | D20: =IF($B$7=0,0,B20/$B$7) -> 0.11580828
A21: =IF($B$4="Agence",INDEX(PARAMETRES!$B$11:$B$16,6),INDEX(PARAMETRES!$B$5:$B$10,6)) -> Conserves | B21: =SUMIFS(t_Ventes[Montant_USD],t_Ventes[Agence],IF($B$4="Agence",$B$5,$A21),t_Ventes[Famille],IF($B$4="Agence",$A21,$B$5)) -> 4674.12 | C21: =COUNTIFS(t_Ventes[Agence],IF($B$4="Agence",$B$5,$A21),t_Ventes[Famille],IF($B$4="Agence",$A21,$B$5)) -> 209 | D21: =IF($B$7=0,0,B21/$B$7) -> 0.012050771
A22: Total | B22: =SUM(B16:B21) -> 387868.97 | C22: =SUM(C16:C21) -> 1567

Sheet JOURNAL
A1: Le journal d'exécution
A2: Une ligne par rapport produit. Une macro qui ne laisse pas de trace est une macro dont on ne peut rien dire le lendemain.
A4: Horodatage | B4: Fichier | C4: Statut | D4: Lignes | E4: Total_USD | F4: Message
A5: 46286.321 | B5: 2026-08_Agence_Kinshasa.pdf | C5: OK | D5: 1567 | E5: 387868.97
A6: 46286.321 | B6: 2026-08_Agence_Lubumbashi.pdf | C6: OK | D6: 725 | E6: 219953.12
A7: 46286.321 | B7: 2026-08_Agence_Abidjan.pdf | C7: OK | D7: 1247 | E7: 402516.35
A8: 46286.321 | B8: 2026-08_Agence_Dakar.pdf | C8: OK | D8: 635 | E8: 162151.38
A9: 46286.321 | B9: 2026-08_Agence_Douala.pdf | C9: OK | D9: 676 | E9: 194444.31
A10: 46286.321 | B10: 2026-08_Agence_Libreville.pdf | C10: OK | D10: 787 | E10: 305853.78
A11: 46286.321 | B11: 2026-08_Famille_Huiles.pdf | C11: OK | D11: 1184 | E11: 279286.53
A12: 46286.321 | B12: 2026-08_Famille_Riz.pdf | C12: OK | D12: 1484 | E12: 790854.58
A13: 46286.321 | B13: 2026-08_Famille_Farine.pdf | C13: OK | D13: 988 | E13: 339712.77
A14: 46286.321 | B14: 2026-08_Famille_Boissons.pdf | C14: OK | D14: 675 | E14: 81306.67
A15: 46286.321 | B15: 2026-08_Famille_Savons.pdf | C15: OK | D15: 556 | E15: 159883.22
A16: 46286.321 | B16: 2026-08_Famille_Conserves.pdf | C16: OK | D16: 750 | E16: 21744.14

Sheet QUALITE
A1: Contrôles de qualité
A2: Sept contrôles, à passer avant d'envoyer quoi que ce soit. Ils se relancent tout seuls le mois prochain.
A4: Contrôle | B4: Valeur | C4: Ce que ça veut dire
A5: Classeurs manquants · doit valoir 0 | B5: =200-ROWS(t_Sources[Fichier]) -> 0 | C5: deux cents fichiers reçus, deux cents fichiers lus
A6: Fichiers vides portant quand même un total · doit valoir 0 | B6: =COUNTIFS(t_Sources[Lignes],0,t_Sources[Total_USD],"<>0") -> 0 | C6: un fichier sans ligne doit totaliser zéro, pas « rien »
A7: Montants négatifs dans le consolidé · doit valoir 0 | B7: =SUMPRODUCT((t_Ventes[Montant_USD]<0)*1) -> 0 | C7: un avoir existe, mais il ne se glisse pas ici sans qu'on le sache
A8: Lignes sans agence · doit valoir 0 | B8: =ROWS(t_Ventes[Agence])-COUNTIF(t_Ventes[Agence],"?*") -> 0 | C8: une ligne orpheline ne sortira dans aucun des douze rapports
A9: Rapports attendus manquants · doit valoir 0 | B9: =12-ROWS(t_Rapports[Nom_Fichier]) -> 0 | C9: six agences et six familles
A10: Le journal contient-il un échec ? | B10: =IF(COUNTIF(t_Journal[Statut],"KO")=0,"PASS","FAIL") -> PASS | C10: un seul KO interdit l'envoi — même si onze PDF sont justes
A11: La réconciliation passe-t-elle ? | B11: =IF(REPONSES!$B$16=0,"PASS","FAIL") -> PASS | C11: c'est le contrôle qui vaut tous les autres

Sheet REPONSES
A1: TP 10 — Le lundi matin d'Aïcha
A2: Les deux premières se lisent après avoir lancé la macro. Les autres se calculent, et elles se calculent même si la macro n'a pas encore tourné.
A4: ① CE QUE VOUS LISEZ APRÈS EXÉCUTION
A5: Durée d'exécution de la macro, en secondes | B5: 37.4
A6: Nombre de PDF réellement présents dans le dossier de sortie | B6: 12
A8: ② CE QUE LES FORMULES VÉRIFIENT
A10: Nombre de classeurs clients reçus | B10: =ROWS(t_Sources[Fichier]) -> 200
A11: Nombre de classeurs vides | B11: =COUNTIF(t_Sources[Lignes],0) -> 4
A12: Nombre de classeurs porteurs d'une anomalie | B12: =COUNTIF(t_Sources[Anomalie],"?*") -> 15
A13: Nombre de clients ayant commandé | B13: =COUNTIF(t_Sources[Lignes],">0") -> 196
A14: Nombre de lignes consolidées | B14: =ROWS(t_Ventes[Date]) -> 5637
A15: Total consolidé, en USD | B15: =SUM(t_Ventes[Montant_USD]) -> 1672787.9
A16: R_ECART_SOURCES — consolidé moins récapitulatif · doit valoir 0 | B16: =ROUND(B15-SUM(t_Sources[Total_USD]),2) -> 0
A17: Écart entre les deux méthodes de conversion | B17: =ROUND(SUM(t_Sources[Total_USD_direct])-SUM(t_Sources[Total_USD]),2) -> 0.54
A18: Nombre de rapports à produire | B18: =ROWS(t_Rapports[Nom_Fichier]) -> 12
A19: Somme des six rapports d'agence | B19: =SUMIF(t_Rapports[Type],"Agence",t_Rapports[Total_USD]) -> 1672787.9
A20: R_ECART_AGENCES — la découpe par agence · doit valoir 0 | B20: =ROUND(B19-B15,2) -> 0
A21: R_ECART_FAMILLES — la découpe par famille · doit valoir 0 | B21: =ROUND(SUMIF(t_Rapports[Type],"Famille",t_Rapports[Total_USD])-B15,2) -> 0
A22: Rapports effectivement produits, d'après le journal | B22: =COUNTIF(t_Journal[Statut],"OK") -> 12
A23: Le plus gros client du mois, en USD | B23: =MAX(t_Sources[Total_USD]) -> 89558.99
A24: Son nom | B24: =INDEX(t_Sources[Client],MATCH(MAX(t_Sources[Total_USD]),t_Sources[Total_USD],0)) -> Ets Essomba & Fils
A25: Clients au-dessus de 20 000 USD sur le mois | B25: =COUNTIF(t_Sources[Total_USD],">20000") -> 17
A26: R_CONTROLE — quantité × prix moins le montant · doit valoir 0 | B26: =ROUND(SUMPRODUCT(t_Ventes[Quantite],t_Ventes[PU_Local])-SUM(t_Ventes[Montant_Local]),0) -> 0

Sheet ANNEXE_IA
A1: ANNEXE_IA
A3: Le prompt qui a produit la macro | B3: Ce que vous avez demandé, mot pour mot.
A4: Ce que l'IA a écrit et qui était faux | B4: Décrivez précisément l'erreur, et comment vous l'avez vue.
A5: Le V qui l'a attrapée | B5: V1 source · V2 calcul · V3 cohérence · V4 terrain · V5 lisibilité.
A6: Ce que vous avez corrigé dans le code | B6: Ligne par ligne, ce qui a changé et pourquoi.
A7: Ce que vous n'avez pas suivi | B7: Une suggestion de l'IA que vous avez écartée, et pourquoi.
